{
    "LogisticRegression": {
        "error": "\nAll the 5 fits failed.\nIt is very likely that your model is misconfigured.\nYou can try to debug the error by setting error_score='raise'.\n\nBelow are more details about the failures:\n--------------------------------------------------------------------------------\n5 fits failed with the following error:\nTraceback (most recent call last):\n  File \"/Users/nikhilmalkari/anaconda3/envs/autobench/lib/python3.9/site-packages/sklearn/model_selection/_validation.py\", line 888, in _fit_and_score\n    estimator.fit(X_train, y_train, **fit_params)\n  File \"/Users/nikhilmalkari/anaconda3/envs/autobench/lib/python3.9/site-packages/sklearn/base.py\", line 1473, in wrapper\n    return fit_method(estimator, *args, **kwargs)\n  File \"/Users/nikhilmalkari/anaconda3/envs/autobench/lib/python3.9/site-packages/sklearn/linear_model/_logistic.py\", line 1223, in fit\n    X, y = self._validate_data(\n  File \"/Users/nikhilmalkari/anaconda3/envs/autobench/lib/python3.9/site-packages/sklearn/base.py\", line 650, in _validate_data\n    X, y = check_X_y(X, y, **check_params)\n  File \"/Users/nikhilmalkari/anaconda3/envs/autobench/lib/python3.9/site-packages/sklearn/utils/validation.py\", line 1318, in check_X_y\n    y = _check_y(y, multi_output=multi_output, y_numeric=y_numeric, estimator=estimator)\n  File \"/Users/nikhilmalkari/anaconda3/envs/autobench/lib/python3.9/site-packages/sklearn/utils/validation.py\", line 1339, in _check_y\n    y = column_or_1d(y, warn=True)\n  File \"/Users/nikhilmalkari/anaconda3/envs/autobench/lib/python3.9/site-packages/sklearn/utils/validation.py\", line 1406, in column_or_1d\n    raise ValueError(\nValueError: y should be a 1d array, got an array of shape (320, 5) instead.\n"
    },
    "DecisionTree": {
        "error": "multilabel-indicator is not supported"
    },
    "RandomForest": {
        "error": "multilabel-indicator is not supported"
    },
    "SupportVectorMachine": {
        "error": "\nAll the 5 fits failed.\nIt is very likely that your model is misconfigured.\nYou can try to debug the error by setting error_score='raise'.\n\nBelow are more details about the failures:\n--------------------------------------------------------------------------------\n5 fits failed with the following error:\nTraceback (most recent call last):\n  File \"/Users/nikhilmalkari/anaconda3/envs/autobench/lib/python3.9/site-packages/sklearn/model_selection/_validation.py\", line 888, in _fit_and_score\n    estimator.fit(X_train, y_train, **fit_params)\n  File \"/Users/nikhilmalkari/anaconda3/envs/autobench/lib/python3.9/site-packages/sklearn/base.py\", line 1473, in wrapper\n    return fit_method(estimator, *args, **kwargs)\n  File \"/Users/nikhilmalkari/anaconda3/envs/autobench/lib/python3.9/site-packages/sklearn/svm/_base.py\", line 190, in fit\n    X, y = self._validate_data(\n  File \"/Users/nikhilmalkari/anaconda3/envs/autobench/lib/python3.9/site-packages/sklearn/base.py\", line 650, in _validate_data\n    X, y = check_X_y(X, y, **check_params)\n  File \"/Users/nikhilmalkari/anaconda3/envs/autobench/lib/python3.9/site-packages/sklearn/utils/validation.py\", line 1318, in check_X_y\n    y = _check_y(y, multi_output=multi_output, y_numeric=y_numeric, estimator=estimator)\n  File \"/Users/nikhilmalkari/anaconda3/envs/autobench/lib/python3.9/site-packages/sklearn/utils/validation.py\", line 1339, in _check_y\n    y = column_or_1d(y, warn=True)\n  File \"/Users/nikhilmalkari/anaconda3/envs/autobench/lib/python3.9/site-packages/sklearn/utils/validation.py\", line 1406, in column_or_1d\n    raise ValueError(\nValueError: y should be a 1d array, got an array of shape (320, 5) instead.\n"
    },
    "GradientBoosting": {
        "error": "\nAll the 5 fits failed.\nIt is very likely that your model is misconfigured.\nYou can try to debug the error by setting error_score='raise'.\n\nBelow are more details about the failures:\n--------------------------------------------------------------------------------\n5 fits failed with the following error:\nTraceback (most recent call last):\n  File \"/Users/nikhilmalkari/anaconda3/envs/autobench/lib/python3.9/site-packages/sklearn/model_selection/_validation.py\", line 888, in _fit_and_score\n    estimator.fit(X_train, y_train, **fit_params)\n  File \"/Users/nikhilmalkari/anaconda3/envs/autobench/lib/python3.9/site-packages/sklearn/base.py\", line 1473, in wrapper\n    return fit_method(estimator, *args, **kwargs)\n  File \"/Users/nikhilmalkari/anaconda3/envs/autobench/lib/python3.9/site-packages/sklearn/ensemble/_gb.py\", line 665, in fit\n    y = self._encode_y(y=y, sample_weight=None)\n  File \"/Users/nikhilmalkari/anaconda3/envs/autobench/lib/python3.9/site-packages/sklearn/ensemble/_gb.py\", line 1504, in _encode_y\n    encoded_y_int = label_encoder.fit_transform(y)\n  File \"/Users/nikhilmalkari/anaconda3/envs/autobench/lib/python3.9/site-packages/sklearn/preprocessing/_label.py\", line 114, in fit_transform\n    y = column_or_1d(y, warn=True)\n  File \"/Users/nikhilmalkari/anaconda3/envs/autobench/lib/python3.9/site-packages/sklearn/utils/validation.py\", line 1406, in column_or_1d\n    raise ValueError(\nValueError: y should be a 1d array, got an array of shape (320, 5) instead.\n"
    },
    "AdaBoost": {
        "error": "\nAll the 5 fits failed.\nIt is very likely that your model is misconfigured.\nYou can try to debug the error by setting error_score='raise'.\n\nBelow are more details about the failures:\n--------------------------------------------------------------------------------\n5 fits failed with the following error:\nTraceback (most recent call last):\n  File \"/Users/nikhilmalkari/anaconda3/envs/autobench/lib/python3.9/site-packages/sklearn/model_selection/_validation.py\", line 888, in _fit_and_score\n    estimator.fit(X_train, y_train, **fit_params)\n  File \"/Users/nikhilmalkari/anaconda3/envs/autobench/lib/python3.9/site-packages/sklearn/base.py\", line 1473, in wrapper\n    return fit_method(estimator, *args, **kwargs)\n  File \"/Users/nikhilmalkari/anaconda3/envs/autobench/lib/python3.9/site-packages/sklearn/ensemble/_weight_boosting.py\", line 133, in fit\n    X, y = self._validate_data(\n  File \"/Users/nikhilmalkari/anaconda3/envs/autobench/lib/python3.9/site-packages/sklearn/base.py\", line 650, in _validate_data\n    X, y = check_X_y(X, y, **check_params)\n  File \"/Users/nikhilmalkari/anaconda3/envs/autobench/lib/python3.9/site-packages/sklearn/utils/validation.py\", line 1318, in check_X_y\n    y = _check_y(y, multi_output=multi_output, y_numeric=y_numeric, estimator=estimator)\n  File \"/Users/nikhilmalkari/anaconda3/envs/autobench/lib/python3.9/site-packages/sklearn/utils/validation.py\", line 1339, in _check_y\n    y = column_or_1d(y, warn=True)\n  File \"/Users/nikhilmalkari/anaconda3/envs/autobench/lib/python3.9/site-packages/sklearn/utils/validation.py\", line 1406, in column_or_1d\n    raise ValueError(\nValueError: y should be a 1d array, got an array of shape (320, 5) instead.\n"
    },
    "NaiveBayes": {
        "error": "\nAll the 5 fits failed.\nIt is very likely that your model is misconfigured.\nYou can try to debug the error by setting error_score='raise'.\n\nBelow are more details about the failures:\n--------------------------------------------------------------------------------\n5 fits failed with the following error:\nTraceback (most recent call last):\n  File \"/Users/nikhilmalkari/anaconda3/envs/autobench/lib/python3.9/site-packages/sklearn/model_selection/_validation.py\", line 888, in _fit_and_score\n    estimator.fit(X_train, y_train, **fit_params)\n  File \"/Users/nikhilmalkari/anaconda3/envs/autobench/lib/python3.9/site-packages/sklearn/base.py\", line 1473, in wrapper\n    return fit_method(estimator, *args, **kwargs)\n  File \"/Users/nikhilmalkari/anaconda3/envs/autobench/lib/python3.9/site-packages/sklearn/naive_bayes.py\", line 262, in fit\n    y = self._validate_data(y=y)\n  File \"/Users/nikhilmalkari/anaconda3/envs/autobench/lib/python3.9/site-packages/sklearn/base.py\", line 635, in _validate_data\n    out = _check_y(y, **check_params)\n  File \"/Users/nikhilmalkari/anaconda3/envs/autobench/lib/python3.9/site-packages/sklearn/utils/validation.py\", line 1339, in _check_y\n    y = column_or_1d(y, warn=True)\n  File \"/Users/nikhilmalkari/anaconda3/envs/autobench/lib/python3.9/site-packages/sklearn/utils/validation.py\", line 1406, in column_or_1d\n    raise ValueError(\nValueError: y should be a 1d array, got an array of shape (320, 5) instead.\n"
    },
    "KNearestNeighbors": {
        "error": "multilabel-indicator is not supported"
    },
    "NeuralNetwork": {
        "error": "multilabel-indicator is not supported"
    },
    "MultiOutputRandomForest": {
        "error": "multilabel-indicator is not supported"
    }
}